[2025-10-16T09:53:06.603+0000] {local_task_job_runner.py:120} INFO - ::group::Pre task execution logs
[2025-10-16T09:53:06.634+0000] {taskinstance.py:2076} INFO - Dependencies all met for dep_context=non-requeueable deps ti=<TaskInstance: dag2.dag2_bash_1 scheduled__2025-10-16T09:51:00+00:00 [queued]>
[2025-10-16T09:53:06.644+0000] {taskinstance.py:2076} INFO - Dependencies all met for dep_context=requeueable deps ti=<TaskInstance: dag2.dag2_bash_1 scheduled__2025-10-16T09:51:00+00:00 [queued]>
[2025-10-16T09:53:06.646+0000] {taskinstance.py:2306} INFO - Starting attempt 1 of 1
[2025-10-16T09:53:06.658+0000] {taskinstance.py:2330} INFO - Executing <Task(BashOperator): dag2_bash_1> on 2025-10-16 09:51:00+00:00
[2025-10-16T09:53:06.680+0000] {warnings.py:112} WARNING - /home/***/.local/lib/python3.12/site-packages/***/task/task_runner/standard_task_runner.py:61: DeprecationWarning: This process (pid=138) is multi-threaded, use of fork() may lead to deadlocks in the child.
  pid = os.fork()

[2025-10-16T09:53:06.687+0000] {standard_task_runner.py:63} INFO - Started process 142 to run task
[2025-10-16T09:53:06.682+0000] {standard_task_runner.py:90} INFO - Running: ['***', 'tasks', 'run', 'dag2', 'dag2_bash_1', 'scheduled__2025-10-16T09:51:00+00:00', '--job-id', '29', '--raw', '--subdir', 'DAGS_FOLDER/dag2.py', '--cfg-path', '/tmp/tmpv0hh0caz']
[2025-10-16T09:53:06.693+0000] {standard_task_runner.py:91} INFO - Job 29: Subtask dag2_bash_1
[2025-10-16T09:53:06.750+0000] {warnings.py:112} WARNING - /home/***/.local/lib/python3.12/site-packages/***/settings.py:195: DeprecationWarning: The sql_alchemy_conn option in [core] has been moved to the sql_alchemy_conn option in [database] - the old setting has been used, but please update your config.
  SQL_ALCHEMY_CONN = conf.get("database", "SQL_ALCHEMY_CONN")

[2025-10-16T09:53:06.904+0000] {task_command.py:426} INFO - Running <TaskInstance: dag2.dag2_bash_1 scheduled__2025-10-16T09:51:00+00:00 [running]> on host bb861ccd12fb
[2025-10-16T09:53:07.038+0000] {taskinstance.py:2648} INFO - Exporting env vars: AIRFLOW_CTX_DAG_OWNER='***' AIRFLOW_CTX_DAG_ID='dag2' AIRFLOW_CTX_TASK_ID='dag2_bash_1' AIRFLOW_CTX_EXECUTION_DATE='2025-10-16T09:51:00+00:00' AIRFLOW_CTX_TRY_NUMBER='1' AIRFLOW_CTX_DAG_RUN_ID='scheduled__2025-10-16T09:51:00+00:00'
[2025-10-16T09:53:07.039+0000] {taskinstance.py:430} INFO - ::endgroup::
[2025-10-16T09:53:07.040+0000] {subprocess.py:63} INFO - Tmp dir root location: /tmp
[2025-10-16T09:53:07.041+0000] {subprocess.py:75} INFO - Running command: ['/usr/bin/bash', '-c', 'hello bash']
[2025-10-16T09:53:07.054+0000] {subprocess.py:86} INFO - Output:
[2025-10-16T09:53:07.080+0000] {subprocess.py:93} INFO - /usr/bin/bash: line 1: hello: command not found
[2025-10-16T09:53:07.082+0000] {subprocess.py:97} INFO - Command exited with return code 127
[2025-10-16T09:53:07.083+0000] {taskinstance.py:441} INFO - ::group::Post task execution logs
[2025-10-16T09:53:07.092+0000] {taskinstance.py:2905} ERROR - Task failed with exception
Traceback (most recent call last):
  File "/home/airflow/.local/lib/python3.12/site-packages/airflow/models/taskinstance.py", line 465, in _execute_task
    result = _execute_callable(context=context, **execute_callable_kwargs)
             ^^^^^^^^^^^^^^^^^^^^^^^^^^^^^^^^^^^^^^^^^^^^^^^^^^^^^^^^^^^^^
  File "/home/airflow/.local/lib/python3.12/site-packages/airflow/models/taskinstance.py", line 432, in _execute_callable
    return execute_callable(context=context, **execute_callable_kwargs)
           ^^^^^^^^^^^^^^^^^^^^^^^^^^^^^^^^^^^^^^^^^^^^^^^^^^^^^^^^^^^^
  File "/home/airflow/.local/lib/python3.12/site-packages/airflow/models/baseoperator.py", line 401, in wrapper
    return func(self, *args, **kwargs)
           ^^^^^^^^^^^^^^^^^^^^^^^^^^^
  File "/home/airflow/.local/lib/python3.12/site-packages/airflow/operators/bash.py", line 243, in execute
    raise AirflowException(
airflow.exceptions.AirflowException: Bash command failed. The command returned a non-zero exit code 127.
[2025-10-16T09:53:07.098+0000] {taskinstance.py:1206} INFO - Marking task as FAILED. dag_id=dag2, task_id=dag2_bash_1, run_id=scheduled__2025-10-16T09:51:00+00:00, execution_date=20251016T095100, start_date=20251016T095306, end_date=20251016T095307
[2025-10-16T09:53:07.109+0000] {standard_task_runner.py:110} ERROR - Failed to execute job 29 for task dag2_bash_1 (Bash command failed. The command returned a non-zero exit code 127.; 142)
[2025-10-16T09:53:07.148+0000] {local_task_job_runner.py:240} INFO - Task exited with return code 1
[2025-10-16T09:53:07.174+0000] {taskinstance.py:3503} INFO - 0 downstream tasks scheduled from follow-on schedule check
[2025-10-16T09:53:07.178+0000] {local_task_job_runner.py:222} INFO - ::endgroup::
