[2025-10-16T13:52:10.363+0000] {local_task_job_runner.py:120} INFO - ::group::Pre task execution logs
[2025-10-16T13:52:10.392+0000] {taskinstance.py:2076} INFO - Dependencies all met for dep_context=non-requeueable deps ti=<TaskInstance: email_task.task_sql manual__2025-10-16T13:52:07.960724+00:00 [queued]>
[2025-10-16T13:52:10.400+0000] {taskinstance.py:2076} INFO - Dependencies all met for dep_context=requeueable deps ti=<TaskInstance: email_task.task_sql manual__2025-10-16T13:52:07.960724+00:00 [queued]>
[2025-10-16T13:52:10.403+0000] {taskinstance.py:2306} INFO - Starting attempt 1 of 1
[2025-10-16T13:52:10.417+0000] {taskinstance.py:2330} INFO - Executing <Task(PythonOperator): task_sql> on 2025-10-16 13:52:07.960724+00:00
[2025-10-16T13:52:10.426+0000] {warnings.py:112} WARNING - /home/***/.local/lib/python3.12/site-packages/***/task/task_runner/standard_task_runner.py:61: DeprecationWarning: This process (pid=199) is multi-threaded, use of fork() may lead to deadlocks in the child.
  pid = os.fork()

[2025-10-16T13:52:10.428+0000] {standard_task_runner.py:63} INFO - Started process 201 to run task
[2025-10-16T13:52:10.427+0000] {standard_task_runner.py:90} INFO - Running: ['***', 'tasks', 'run', 'email_task', 'task_sql', 'manual__2025-10-16T13:52:07.960724+00:00', '--job-id', '144', '--raw', '--subdir', 'DAGS_FOLDER/email_task.py', '--cfg-path', '/tmp/tmp9f0_so0j']
[2025-10-16T13:52:10.430+0000] {standard_task_runner.py:91} INFO - Job 144: Subtask task_sql
[2025-10-16T13:52:10.445+0000] {warnings.py:112} WARNING - /home/***/.local/lib/python3.12/site-packages/***/settings.py:195: DeprecationWarning: The sql_alchemy_conn option in [core] has been moved to the sql_alchemy_conn option in [database] - the old setting has been used, but please update your config.
  SQL_ALCHEMY_CONN = conf.get("database", "SQL_ALCHEMY_CONN")

[2025-10-16T13:52:10.501+0000] {task_command.py:426} INFO - Running <TaskInstance: email_task.task_sql manual__2025-10-16T13:52:07.960724+00:00 [running]> on host a31b0a3647d9
[2025-10-16T13:52:10.583+0000] {taskinstance.py:2648} INFO - Exporting env vars: AIRFLOW_CTX_DAG_OWNER='***' AIRFLOW_CTX_DAG_ID='email_task' AIRFLOW_CTX_TASK_ID='task_sql' AIRFLOW_CTX_EXECUTION_DATE='2025-10-16T13:52:07.960724+00:00' AIRFLOW_CTX_TRY_NUMBER='1' AIRFLOW_CTX_DAG_RUN_ID='manual__2025-10-16T13:52:07.960724+00:00'
[2025-10-16T13:52:10.585+0000] {taskinstance.py:430} INFO - ::endgroup::
[2025-10-16T13:52:10.588+0000] {taskinstance.py:441} INFO - ::group::Post task execution logs
[2025-10-16T13:52:10.590+0000] {taskinstance.py:2905} ERROR - Task failed with exception
Traceback (most recent call last):
  File "/home/airflow/.local/lib/python3.12/site-packages/airflow/models/taskinstance.py", line 465, in _execute_task
    result = _execute_callable(context=context, **execute_callable_kwargs)
             ^^^^^^^^^^^^^^^^^^^^^^^^^^^^^^^^^^^^^^^^^^^^^^^^^^^^^^^^^^^^^
  File "/home/airflow/.local/lib/python3.12/site-packages/airflow/models/taskinstance.py", line 432, in _execute_callable
    return execute_callable(context=context, **execute_callable_kwargs)
           ^^^^^^^^^^^^^^^^^^^^^^^^^^^^^^^^^^^^^^^^^^^^^^^^^^^^^^^^^^^^
  File "/home/airflow/.local/lib/python3.12/site-packages/airflow/models/baseoperator.py", line 401, in wrapper
    return func(self, *args, **kwargs)
           ^^^^^^^^^^^^^^^^^^^^^^^^^^^
  File "/home/airflow/.local/lib/python3.12/site-packages/airflow/operators/python.py", line 235, in execute
    return_value = self.execute_callable()
                   ^^^^^^^^^^^^^^^^^^^^^^^
  File "/home/airflow/.local/lib/python3.12/site-packages/airflow/operators/python.py", line 252, in execute_callable
    return self.python_callable(*self.op_args, **self.op_kwargs)
           ^^^^^^^^^^^^^^^^^^^^^^^^^^^^^^^^^^^^^^^^^^^^^^^^^^^^^
  File "/opt/airflow/dags/email_task.py", line 9, in connect_to_sqlserver
    conn = pyodbc.connect(
           ^^^^^^^^^^^^^^^
pyodbc.Error: ('01000', "[01000] [unixODBC][Driver Manager]Can't open lib 'ODBC Driver 17 for SQL Server' : file not found (0) (SQLDriverConnect)")
[2025-10-16T13:52:10.607+0000] {taskinstance.py:1206} INFO - Marking task as FAILED. dag_id=email_task, task_id=task_sql, run_id=manual__2025-10-16T13:52:07.960724+00:00, execution_date=20251016T135207, start_date=20251016T135210, end_date=20251016T135210
[2025-10-16T13:52:10.621+0000] {standard_task_runner.py:110} ERROR - Failed to execute job 144 for task task_sql (('01000', "[01000] [unixODBC][Driver Manager]Can't open lib 'ODBC Driver 17 for SQL Server' : file not found (0) (SQLDriverConnect)"); 201)
[2025-10-16T13:52:10.651+0000] {local_task_job_runner.py:240} INFO - Task exited with return code 1
[2025-10-16T13:52:10.674+0000] {taskinstance.py:3503} INFO - 0 downstream tasks scheduled from follow-on schedule check
[2025-10-16T13:52:10.680+0000] {local_task_job_runner.py:222} INFO - ::endgroup::
